Workbook

Sheet Cartas
A1: Desvario: O Reino do Avesso · Catálogo de cartas (33)
A2: Legenda: a cor da coluna 'Categoria' segue a moldura da carta (amarelo = Normal, laranja = Efeito, verde = Magia, rosa = Armadilha). ★ = prioridade para a Entrega 1. Colunas AMARELAS (Status da arte / Observações) são para você preencher.
A4: Código | B4: Nome | C4: Categoria | D4: Subtipo | E4: Nível (★) | F4: Atributo | G4: Tipo de monstro | H4: ATK | I4: DEF | J4: Deck | K4: Cópias no deck | L4: Prioridade | M4: Região | N4: Efeito | O4: Texto de história | P4: Ideia de arte | Q4: Nome do arquivo da arte | R4: Status da arte | S4: Observações | T4: Prompt pronto (IA)
A5: DSV-001 | B5: Sr. Pontual, o Caracol Cronista | C5: Monstro Normal | D5: Normal | E5: 2 | F5: TEMPO | G5: Fera | H5: 700 | I5: 1200 | J5: A · Sonhadores de Desvario | K5: 2 | M5: Bosque das Horas Tortas | N5: — | O5: Carrega nas costas um relógio que nunca acertou a hora. Ainda assim, chega sempre no momento exato em que ninguém o esperava. | P5: Caracol gordinho e simpático, de monóculo e cachecol, que carrega um relógio de bolso de latão enorme no lugar da concha. Os ponteiros andam ao contrário. Trilha de musgo com números romanos caídos pelo chão. | Q5: dsv-001-sr-pontual.webp | R5: Entregue | T5: Crie uma ilustração QUADRADA (1:1) para a arte de uma carta de um jogo de cartas de fantasia chamado Desvario. Estilo: ilustração de livro de contos em aquarela e nanquim, muito detalhada, traço fino, clima caprichoso e surreal, o MESMO estilo da imagem de referência do Sr. Pontual. Carta DSV-001, "Sr. Pontual, o Caracol Cronista". Cena: Caracol gordinho e simpático, de monóculo e cachecol, que carrega um relógio de bolso de latão enorme no lugar da concha. Os ponteiros andam ao contrário. Trilha de musgo com números romanos caídos pelo chão. Paleta: cores quentes, vivas e saturadas; formas curvas e orgânicas. Composição: assunto principal centralizado e inteiro, ocupando cerca de 60% da imagem, com cenário ao fundo e margem livre nas bordas; precisa ser legível em miniatura. IMPORTANTE: apenas a ilustração, SEM moldura, SEM borda, SEM nome da carta, SEM estrelas, SEM ATK/DEF, SEM textos ou letreiros e SEM marca d'água.
A6: DSV-002 | B6: Capitão Botão | C6: Monstro Normal | D6: Normal | E6: 4 | F6: TINTA | G6: Brinquedo | H6: 1700 | I6: 1300 | J6: A · Sonhadores de Desvario | K6: 3 | L6: ★ | M6: Jardim de Xadrez Vivo | N6: — | O6: Costurado com botões de mil casacos esquecidos. Jurou proteger Desvario até que a última linha se solte. | P6: Soldado de brinquedo feito inteiramente de botões coloridos, costurados com linha vermelha. Agulha de costura como espada e dedal como capacete. Pose heroica sobre um carretel. | Q6: dsv-002-capitao-botao.webp | R6: Entregue | T6: Crie uma ilustração QUADRADA (1:1) para a arte de uma carta de um jogo de cartas de fantasia chamado Desvario. Estilo: ilustração de livro de contos em aquarela e nanquim, muito detalhada, traço fino, clima caprichoso e surreal, o MESMO estilo da imagem de referência do Sr. Pontual. Carta DSV-002, "Capitão Botão". Cena: Soldado de brinquedo feito inteiramente de botões coloridos, costurados com linha vermelha. Agulha de costura como espada e dedal como capacete. Pose heroica sobre um carretel. Paleta: cores quentes, vivas e saturadas; formas curvas e orgânicas. Composição: assunto principal centralizado e inteiro, ocupando cerca de 60% da imagem, com cenário ao fundo e margem livre nas bordas; precisa ser legível em miniatura. IMPORTANTE: apenas a ilustração, SEM moldura, SEM borda, SEM nome da carta, SEM estrelas, SEM ATK/DEF, SEM textos ou letreiros e SEM marca d'água.
A7: DSV-003 | B7: Margarida Fofoqueira | C7: Monstro Normal | D7: Normal | E7: 3 | F7: FOLHA | G7: Planta | H7: 1200 | I7: 1000 | J7: A · Sonhadores de Desvario | K7: 2 | M7: Jardim de Xadrez Vivo | N7: — | O7: Sabe todos os segredos do jardim e conta todos eles, principalmente os que ainda não aconteceram. | P7: Margarida gigante de rosto expressivo, cochichando com a mão-folha na frente da boca. Flores menores escutam, curiosas. Canteiros em formato de tabuleiro. | Q7: dsv-003-margarida-fofoqueira.webp | R7: Entregue | T7: Crie uma ilustração QUADRADA (1:1) para a arte de uma carta de um jogo de cartas de fantasia chamado Desvario. Estilo: ilustração de livro de contos em aquarela e nanquim, muito detalhada, traço fino, clima caprichoso e surreal, o MESMO estilo da imagem de referência do Sr. Pontual. Carta DSV-003, "Margarida Fofoqueira". Cena: Margarida gigante de rosto expressivo, cochichando com a mão-folha na frente da boca. Flores menores escutam, curiosas. Canteiros em formato de tabuleiro. Paleta: cores quentes, vivas e saturadas; formas curvas e orgânicas. Composição: assunto principal centralizado e inteiro, ocupando cerca de 60% da imagem, com cenário ao fundo e margem livre nas bordas; precisa ser legível em miniatura. IMPORTANTE: apenas a ilustração, SEM moldura, SEM borda, SEM nome da carta, SEM estrelas, SEM ATK/DEF, SEM textos ou letreiros e SEM marca d'água.
A8: DSV-004 | B8: Dragão Ponteiro | C8: Monstro Normal | D8: Normal | E8: 7 | F8: TEMPO | G8: Fera | H8: 2500 | I8: 2000 | J8: A · Sonhadores de Desvario | K8: 2 | L8: ★ | M8: Bosque das Horas Tortas | N8: — | O8: Dizem que seu rugido atrasa o dia inteiro em uma hora. Os relojoeiros de Desvario o temem e o adoram. | P8: Dragão imponente de bronze e engrenagens, com mostrador de relógio no peito e asas formadas por ponteiros. Ampulhetas pendem dos chifres. Céu crepuscular com vários sóis em horários diferentes. | Q8: dsv-004-dragao-ponteiro.webp | R8: Entregue | T8: Crie uma ilustração QUADRADA (1:1) para a arte de uma carta de um jogo de cartas de fantasia chamado Desvario. Estilo: ilustração de livro de contos em aquarela e nanquim, muito detalhada, traço fino, clima caprichoso e surreal, o MESMO estilo da imagem de referência do Sr. Pontual. Carta DSV-004, "Dragão Ponteiro". Cena: Dragão imponente de bronze e engrenagens, com mostrador de relógio no peito e asas formadas por ponteiros. Ampulhetas pendem dos chifres. Céu crepuscular com vários sóis em horários diferentes. Paleta: cores quentes, vivas e saturadas; formas curvas e orgânicas. Composição: assunto principal centralizado e inteiro, ocupando cerca de 60% da imagem, com cenário ao fundo e margem livre nas bordas; precisa ser legível em miniatura. IMPORTANTE: apenas a ilustração, SEM moldura, SEM borda, SEM nome da carta, SEM estrelas, SEM ATK/DEF, SEM textos ou letreiros e SEM marca d'água.
A9: DSV-005 | B9: Régua Sentinela | C9: Monstro Normal | D9: Normal | E9: 4 | F9: CINZA | G9: Burocrata | H9: 1800 | I9: 1000 | J9: B · Ordem Cinzenta | K9: 3 | M9: Cidadela Cinzenta | N9: — | O9: Mede tudo, aprova nada. Onde passa, as curvas viram linhas retas. | P9: Soldado alto e magro com o corpo feito de régua de madeira graduada. Olhos são furos de fichário, lança é um lápis apontado. Tudo em cinza; atrás dele, uma paisagem colorida sendo 'endireitada'. | Q9: dsv-005-regua-sentinela.webp | R9: Entregue | T9: Crie uma ilustração QUADRADA (1:1) para a arte de uma carta de um jogo de cartas de fantasia chamado Desvario. Estilo: ilustração de livro de contos em aquarela e nanquim, muito detalhada, traço fino, clima caprichoso e surreal, o MESMO estilo da imagem de referência do Sr. Pontual. Carta DSV-005, "Régua Sentinela". Cena: Soldado alto e magro com o corpo feito de régua de madeira graduada. Olhos são furos de fichário, lança é um lápis apontado. Tudo em cinza; atrás dele, uma paisagem colorida sendo 'endireitada'. Paleta: quase monocromática, em tons de cinza, grafite e nanquim; formas retas, rígidas e geométricas; atmosfera burocrática e opressiva. Se a descrição citar um elemento colorido, ele é a ÚNICA cor da cena. Composição: assunto principal centralizado e inteiro, ocupando cerca de 60% da imagem, com cenário ao fundo e margem livre nas bordas; precisa ser legível em miniatura. IMPORTANTE: apenas a ilustração, SEM moldura, SEM borda, SEM nome da carta, SEM estrelas, SEM ATK/DEF, SEM outros textos além da palavra citada entre aspas na cena, escrita corretamente e SEM marca d'água.
A10: DSV-006 | B10: O Sonhador de Tinta | C10: Monstro de Efeito | D10: Efeito | E10: 4 | F10: TINTA | G10: Sonhador | H10: 1600 | I10: 1400 | J10: A · Sonhadores de Desvario | K10: 3 | L10: ★ | M10: Nosso mundo | N10: Se esta carta destruir um monstro do oponente em batalha, você ganha 500 PL. | O10: Caiu numa poça de tinta e acordou do outro lado. Cada passo que dá devolve uma cor ao mundo. | P10: Jovem aventureiro de capa longa e surrada, mãos e barra da capa manchadas de tinta roxa e turquesa que escorre e pinta o chão cinza por onde pisa. Segura um pincel como varinha. Fundo metade colorido, metade cinzento. | Q10: dsv-006-sonhador-de-tinta.webp | R10: Entregue | T10: Crie uma ilustração QUADRADA (1:1) para a arte de uma carta de um jogo de cartas de fantasia chamado Desvario. Estilo: ilustração de livro de contos em aquarela e nanquim, muito detalhada, traço fino, clima caprichoso e surreal, o MESMO estilo da imagem de referência do Sr. Pontual. Carta DSV-006, "O Sonhador de Tinta". Cena: Jovem aventureiro de capa longa e surrada, mãos e barra da capa manchadas de tinta roxa e turquesa que escorre e pinta o chão cinza por onde pisa. Segura um pincel como varinha. Fundo metade colorido, metade cinzento. Paleta: cores quentes, vivas e saturadas; formas curvas e orgânicas. Composição: assunto principal centralizado e inteiro, ocupando cerca de 60% da imagem, com cenário ao fundo e margem livre nas bordas; precisa ser legível em miniatura. IMPORTANTE: apenas a ilustração, SEM moldura, SEM borda, SEM nome da carta, SEM estrelas, SEM ATK/DEF, SEM textos ou letreiros e SEM marca d'água.
A11: DSV-007 | B11: Madame Bule, a Vidente | C11: Monstro de Efeito | D11: Efeito | E11: 3 | F11: CHÁ | G11: Utensílio | H11: 1000 | I11: 1600 | J11: A · Sonhadores de Desvario | K11: 3 | L11: ★ | M11: Mar de Chá Morno | N11: Quando esta carta for Invocada por Invocação-Normal: olhe as 3 cartas do topo do seu Deck e coloque-as de volta na ordem que quiser. | O11: O chá sabe antes de você. Ela só traduz. | P11: Chaleira de porcelana antiga com rosto de senhora mística, xale estampado e brincos de colher. O vapor do bico forma cartas e símbolos no ar. Mesa com toalha de renda e bola de cristal de açúcar. | Q11: dsv-007-madame-bule.webp | R11: Entregue | T11: Crie uma ilustração QUADRADA (1:1) para a arte de uma carta de um jogo de cartas de fantasia chamado Desvario. Estilo: ilustração de livro de contos em aquarela e nanquim, muito detalhada, traço fino, clima caprichoso e surreal, o MESMO estilo da imagem de referência do Sr. Pontual. Carta DSV-007, "Madame Bule, a Vidente". Cena: Chaleira de porcelana antiga com rosto de senhora mística, xale estampado e brincos de colher. O vapor do bico forma cartas e símbolos no ar. Mesa com toalha de renda e bola de cristal de açúcar. Paleta: cores quentes, vivas e saturadas; formas curvas e orgânicas. Composição: assunto principal centralizado e inteiro, ocupando cerca de 60% da imagem, com cenário ao fundo e margem livre nas bordas; precisa ser legível em miniatura. IMPORTANTE: apenas a ilustração, SEM moldura, SEM borda, SEM nome da carta, SEM estrelas, SEM ATK/DEF, SEM textos ou letreiros e SEM marca d'água.
A12: DSV-008 | B12: Coruja Invertida | C12: Monstro de Efeito | D12: Efeito | E12: 4 | F12: ESPELHO | G12: Fera | H12: 1400 | I12: 1800 | J12: A · Sonhadores de Desvario | K12: 3 | L12: ★ | M12: Biblioteca de Portas | N12: Uma vez por turno: escolha 1 monstro com a face para cima no campo; até o fim deste turno, troque o ATK e a DEF originais dele. | O12: .oãhc o êv amic arp ahlo meuQ (Quem olha pra cima vê o chão.) | P12: Coruja pendurada de cabeça para baixo num galho, mas seu reflexo no lago abaixo está em pé, olhando para o espectador. Olhos enormes como espelhos. Penas prateadas e azuladas com estrelas refletidas. | Q12: dsv-008-coruja-invertida.webp | R12: Entregue | T12: Crie uma ilustração QUADRADA (1:1) para a arte de uma carta de um jogo de cartas de fantasia chamado Desvario. Estilo: ilustração de livro de contos em aquarela e nanquim, muito detalhada, traço fino, clima caprichoso e surreal, o MESMO estilo da imagem de referência do Sr. Pontual. Carta DSV-008, "Coruja Invertida". Cena: Coruja pendurada de cabeça para baixo num galho, mas seu reflexo no lago abaixo está em pé, olhando para o espectador. Olhos enormes como espelhos. Penas prateadas e azuladas com estrelas refletidas. Paleta: cores quentes, vivas e saturadas; formas curvas e orgânicas. Composição: assunto principal centralizado e inteiro, ocupando cerca de 60% da imagem, com cenário ao fundo e margem livre nas bordas; precisa ser legível em miniatura. IMPORTANTE: apenas a ilustração, SEM moldura, SEM borda, SEM nome da carta, SEM estrelas, SEM ATK/DEF, SEM textos ou letreiros e SEM marca d'água.
A13: DSV-009 | B13: Xícara Saltitante | C13: Monstro de Efeito | D13: Efeito | E13: 1 | F13: CHÁ | G13: Utensílio | H13: 300 | I13: 300 | J13: A · Sonhadores de Desvario | K13: 2 | M13: Mar de Chá Morno | N13: Se esta carta for destruída em batalha e enviada ao Cemitério: compre 1 carta. | O13: Pula de pires em pires. Quando cai, sempre derrama algo útil. | P13: Xícara pequena e alegre com perninhas finas, pulando entre pires flutuantes. Gotas de chá dourado formam uma trilha. Fundo creme com papel de parede antigo. | Q13: dsv-009-xicara-saltitante.webp | R13: Entregue | T13: Crie uma ilustração QUADRADA (1:1) para a arte de uma carta de um jogo de cartas de fantasia chamado Desvario. Estilo: ilustração de livro de contos em aquarela e nanquim, muito detalhada, traço fino, clima caprichoso e surreal, o MESMO estilo da imagem de referência do Sr. Pontual. Carta DSV-009, "Xícara Saltitante". Cena: Xícara pequena e alegre com perninhas finas, pulando entre pires flutuantes. Gotas de chá dourado formam uma trilha. Fundo creme com papel de parede antigo. Paleta: cores quentes, vivas e saturadas; formas curvas e orgânicas. Composição: assunto principal centralizado e inteiro, ocupando cerca de 60% da imagem, com cenário ao fundo e margem livre nas bordas; precisa ser legível em miniatura. IMPORTANTE: apenas a ilustração, SEM moldura, SEM borda, SEM nome da carta, SEM estrelas, SEM ATK/DEF, SEM textos ou letreiros e SEM marca d'água.
A14: DSV-010 | B14: Torre Andarilha do Xadrez Vivo | C14: Monstro de Efeito | D14: Efeito | E14: 5 | F14: FOLHA | G14: Brinquedo | H14: 2000 | I14: 2200 | J14: A · Sonhadores de Desvario | K14: 2 | M14: Jardim de Xadrez Vivo | N14: Você pode Invocar esta carta por Invocação-Normal sem Tributo. Se fizer isso, o ATK original dela se torna 1000. | O14: Nunca anda em linha reta, o que deixa as outras peças do tabuleiro furiosas. | P14: Torre de xadrez gigante de pedra coberta de hera e flores, andando com pernas de raízes por um jardim quadriculado. Peões-cogumelo fogem do caminho. | Q14: dsv-010-torre-andarilha-do-xadrez-vivo.webp | R14: Entregue | T14: Crie uma ilustração QUADRADA (1:1) para a arte de uma carta de um jogo de cartas de fantasia chamado Desvario. Estilo: ilustração de livro de contos em aquarela e nanquim, muito detalhada, traço fino, clima caprichoso e surreal, o MESMO estilo da imagem de referência do Sr. Pontual. Carta DSV-010, "Torre Andarilha do Xadrez Vivo". Cena: Torre de xadrez gigante de pedra coberta de hera e flores, andando com pernas de raízes por um jardim quadriculado. Peões-cogumelo fogem do caminho. Paleta: cores quentes, vivas e saturadas; formas curvas e orgânicas. Composição: assunto principal centralizado e inteiro, ocupando cerca de 60% da imagem, com cenário ao fundo e margem livre nas bordas; precisa ser legível em miniatura. IMPORTANTE: apenas a ilustração, SEM moldura, SEM borda, SEM nome da carta, SEM estrelas, SEM ATK/DEF, SEM textos ou letreiros e SEM marca d'água.
A15: DSV-011 | B15: A Fiandeira de Sombras | C15: Monstro de Efeito | D15: Efeito | E15: 6 | F15: ESPELHO | G15: Sonhador | H15: 2300 | I15: 1800 | J15: A · Sonhadores de Desvario | K15: 2 | L15: ★ | M15: Biblioteca de Portas | N15: Quando esta carta for Invocada por Invocação-Tributo: escolha 1 Magia ou Armadilha no campo e destrua-a. | O15: Tece caminhos que só existem enquanto ninguém olha para eles. | P15: Figura esguia e elegante de vários braços finos, tecendo fios prateados que viram pontes e escadas no ar. Rosto parcialmente oculto por um véu espelhado. Fundo noturno azul-escuro com constelações costuradas. | Q15: dsv-011-fiandeira-de-sombras.webp | R15: Entregue | T15: Crie uma ilustração QUADRADA (1:1) para a arte de uma carta de um jogo de cartas de fantasia chamado Desvario. Estilo: ilustração de livro de contos em aquarela e nanquim, muito detalhada, traço fino, clima caprichoso e surreal, o MESMO estilo da imagem de referência do Sr. Pontual. Carta DSV-011, "A Fiandeira de Sombras". Cena: Figura esguia e elegante de vários braços finos, tecendo fios prateados que viram pontes e escadas no ar. Rosto parcialmente oculto por um véu espelhado. Fundo noturno azul-escuro com constelações costuradas. Paleta: cores quentes, vivas e saturadas; formas curvas e orgânicas. Composição: assunto principal centralizado e inteiro, ocupando cerca de 60% da imagem, com cenário ao fundo e margem livre nas bordas; precisa ser legível em miniatura. IMPORTANTE: apenas a ilustração, SEM moldura, SEM borda, SEM nome da carta, SEM estrelas, SEM ATK/DEF, SEM textos ou letreiros e SEM marca d'água.
A16: DSV-012 | B16: Carimbador Cinzento | C16: Monstro de Efeito | D16: Efeito (FLIP) | E16: 3 | F16: CINZA | G16: Burocrata | H16: 1300 | I16: 900 | J16: B · Ordem Cinzenta | K16: 2 | L16: ★ | M16: Cidadela Cinzenta | N16: FLIP: escolha 1 monstro que o oponente controla e destrua-o. | O16: INDEFERIDO. INDEFERIDO. INDEFERIDO. | P16: Homenzinho atarracado de terno cinza com um carimbo gigante no lugar da cabeça, carimbando uma flor colorida que vira cinza na hora. Pilhas de papéis. Tudo cinza, exceto a flor. | Q16: dsv-012-carimbador-cinzento.webp | R16: Entregue | T16: Crie uma ilustração QUADRADA (1:1) para a arte de uma carta de um jogo de cartas de fantasia chamado Desvario. Estilo: ilustração de livro de contos em aquarela e nanquim, muito detalhada, traço fino, clima caprichoso e surreal, o MESMO estilo da imagem de referência do Sr. Pontual. Carta DSV-012, "Carimbador Cinzento". Cena: Homenzinho atarracado de terno cinza com um carimbo gigante no lugar da cabeça, carimbando uma flor colorida que vira cinza na hora. Pilhas de papéis. Tudo cinza, exceto a flor. Paleta: quase monocromática, em tons de cinza, grafite e nanquim; formas retas, rígidas e geométricas; atmosfera burocrática e opressiva. Se a descrição citar um elemento colorido, ele é a ÚNICA cor da cena. Composição: assunto principal centralizado e inteiro, ocupando cerca de 60% da imagem, com cenário ao fundo e margem livre nas bordas; precisa ser legível em miniatura. IMPORTANTE: apenas a ilustração, SEM moldura, SEM borda, SEM nome da carta, SEM estrelas, SEM ATK/DEF, SEM textos ou letreiros e SEM marca d'água.
A17: DSV-013 | B17: O Arquiteto Cinzento | C17: Monstro de Efeito | D17: Efeito | E17: 8 | F17: CINZA | G17: Burocrata | H17: 3000 | I17: 2500 | J17: B · Ordem Cinzenta | K17: 2 | L17: ★ | M17: Cidadela Cinzenta | N17: Enquanto esta carta estiver com a face para cima no campo, todos os monstros que o oponente controla perdem 500 de ATK. | O17: Um mundo sem absurdo é um mundo sem erros. E um mundo sem erros é perfeito. | P17: Figura altíssima e rígida, sobretudo cinza impecável e cartola retangular, rosto liso sem traços. Esquadro e compasso gigantes nas mãos. Atrás dele, a cidade colorida vira uma planta arquitetônica cinza. Só os olhos brilham, brancos. | Q17: dsv-013-arquiteto-cinzento.webp | R17: Entregue | T17: Crie uma ilustração QUADRADA (1:1) para a arte de uma carta de um jogo de cartas de fantasia chamado Desvario. Estilo: ilustração de livro de contos em aquarela e nanquim, muito detalhada, traço fino, clima caprichoso e surreal, o MESMO estilo da imagem de referência do Sr. Pontual. Carta DSV-013, "O Arquiteto Cinzento". Cena: Figura altíssima e rígida, sobretudo cinza impecável e cartola retangular, rosto liso sem traços. Esquadro e compasso gigantes nas mãos. Atrás dele, a cidade colorida vira uma planta arquitetônica cinza. Só os olhos brilham, brancos. Paleta: quase monocromática, em tons de cinza, grafite e nanquim; formas retas, rígidas e geométricas; atmosfera burocrática e opressiva. Se a descrição citar um elemento colorido, ele é a ÚNICA cor da cena. Composição: assunto principal centralizado e inteiro, ocupando cerca de 60% da imagem, com cenário ao fundo e margem livre nas bordas; precisa ser legível em miniatura. IMPORTANTE: apenas a ilustração, SEM moldura, SEM borda, SEM nome da carta, SEM estrelas, SEM ATK/DEF, SEM textos ou letreiros e SEM marca d'água.
A18: DSV-014 | B18: Poça de Tinta | C18: Magia | D18: Magia Normal | J18: A · Sonhadores de Desvario | K18: 3 | L18: ★ | M18: Nosso mundo | N18: Adicione 1 monstro de Nível 4 ou menor do seu Deck à sua mão. | P18: Poça de tinta roxa e turquesa numa rua comum do nosso mundo, refletindo um céu impossível com luas e bules flutuando. Uma mão está entrando na poça. | Q18: dsv-014-poca-de-tinta.webp | R18: Entregue | T18: Crie uma ilustração QUADRADA (1:1) para a arte de uma carta de um jogo de cartas de fantasia chamado Desvario. Estilo: ilustração de livro de contos em aquarela e nanquim, muito detalhada, traço fino, clima caprichoso e surreal, o MESMO estilo da imagem de referência do Sr. Pontual. Carta DSV-014, "Poça de Tinta". Cena: Poça de tinta roxa e turquesa numa rua comum do nosso mundo, refletindo um céu impossível com luas e bules flutuando. Uma mão está entrando na poça. Paleta: cores quentes, vivas e saturadas; formas curvas e orgânicas. Composição: assunto principal centralizado e inteiro, ocupando cerca de 60% da imagem, com cenário ao fundo e margem livre nas bordas; precisa ser legível em miniatura. IMPORTANTE: apenas a ilustração, SEM moldura, SEM borda, SEM nome da carta, SEM estrelas, SEM ATK/DEF, SEM textos ou letreiros e SEM marca d'água.
A19: DSV-015 | B19: Bosque das Horas Tortas | C19: Magia | D19: Magia de Campo | J19: A · Sonhadores de Desvario | K19: 2 | L19: ★ | M19: Bosque das Horas Tortas | N19: Todos os monstros TEMPO e FOLHA no campo ganham 300 de ATK e DEF. | P19: Floresta de árvores retorcidas cujos troncos são relógios de pêndulo. Galhos terminam em ponteiros, folhas caem em formato de números. Luz dourada de fim de tarde. Sem personagens. | Q19: dsv-015-bosque-das-horas-tortas.webp | R19: Entregue | T19: Crie uma ilustração QUADRADA (1:1) para a arte de uma carta de um jogo de cartas de fantasia chamado Desvario. Estilo: ilustração de livro de contos em aquarela e nanquim, muito detalhada, traço fino, clima caprichoso e surreal, o MESMO estilo da imagem de referência do Sr. Pontual. Carta DSV-015, "Bosque das Horas Tortas". Cena: Floresta de árvores retorcidas cujos troncos são relógios de pêndulo. Galhos terminam em ponteiros, folhas caem em formato de números. Luz dourada de fim de tarde. Sem personagens. Paleta: cores quentes, vivas e saturadas; formas curvas e orgânicas. Composição: assunto principal centralizado e inteiro, ocupando cerca de 60% da imagem, com cenário ao fundo e margem livre nas bordas; precisa ser legível em miniatura. IMPORTANTE: apenas a ilustração, SEM moldura, SEM borda, SEM nome da carta, SEM estrelas, SEM ATK/DEF, SEM textos ou letreiros e SEM marca d'água.
A20: DSV-016 | B20: Chá Escaldante | C20: Magia | D20: Magia Normal | J20: A · Sonhadores de Desvario | K20: 3 | M20: Mar de Chá Morno | N20: Cause 800 de dano ao oponente. | P20: Bule inclinado derramando um jato de chá fervente em espiral, muito vapor. Soldados-régua cinzentos fogem ao fundo. | Q20: dsv-016-cha-escaldante.webp | R20: Entregue | T20: Crie uma ilustração QUADRADA (1:1) para a arte de uma carta de um jogo de cartas de fantasia chamado Desvario. Estilo: ilustração de livro de contos em aquarela e nanquim, muito detalhada, traço fino, clima caprichoso e surreal, o MESMO estilo da imagem de referência do Sr. Pontual. Carta DSV-016, "Chá Escaldante". Cena: Bule inclinado derramando um jato de chá fervente em espiral, muito vapor. Soldados-régua cinzentos fogem ao fundo. Paleta: cores quentes, vivas e saturadas; formas curvas e orgânicas. Composição: assunto principal centralizado e inteiro, ocupando cerca de 60% da imagem, com cenário ao fundo e margem livre nas bordas; precisa ser legível em miniatura. IMPORTANTE: apenas a ilustração, SEM moldura, SEM borda, SEM nome da carta, SEM estrelas, SEM ATK/DEF, SEM textos ou letreiros e SEM marca d'água.
A21: DSV-017 | B21: Guarda-Chuva de Estrelas | C21: Magia | D21: Magia de Equipamento | J21: A · Sonhadores de Desvario | K21: 2 | M21: Jardim de Xadrez Vivo | N21: O monstro equipado ganha 600 de ATK. | P21: Guarda-chuva aberto e virado para cima, recolhendo estrelas que caem do céu noturno. Cabo de bengala dourada em espiral. | Q21: dsv-017-guarda-chuva-de-estrelas.webp | R21: Entregue | T21: Crie uma ilustração QUADRADA (1:1) para a arte de uma carta de um jogo de cartas de fantasia chamado Desvario. Estilo: ilustração de livro de contos em aquarela e nanquim, muito detalhada, traço fino, clima caprichoso e surreal, o MESMO estilo da imagem de referência do Sr. Pontual. Carta DSV-017, "Guarda-Chuva de Estrelas". Cena: Guarda-chuva aberto e virado para cima, recolhendo estrelas que caem do céu noturno. Cabo de bengala dourada em espiral. Paleta: cores quentes, vivas e saturadas; formas curvas e orgânicas. Composição: assunto principal centralizado e inteiro, ocupando cerca de 60% da imagem, com cenário ao fundo e margem livre nas bordas; precisa ser legível em miniatura. IMPORTANTE: apenas a ilustração, SEM moldura, SEM borda, SEM nome da carta, SEM estrelas, SEM ATK/DEF, SEM textos ou letreiros e SEM marca d'água.
A22: DSV-018 | B22: A Porta Que Não Estava Lá | C22: Armadilha | D22: Armadilha Normal | J22: A · Sonhadores de Desvario | K22: 3 | L22: ★ | M22: Biblioteca de Portas | N22: Quando um monstro do oponente declarar um ataque: anule o ataque e encerre a Fase de Batalha. | P22: Porta de madeira ornamentada, entreaberta, flutuando no meio do nada sem parede. Luz colorida sai pela fresta. Um soldado-régua cinzento dá de cara com ela no meio do ataque. | Q22: dsv-018-porta-que-nao-estava-la.webp | R22: Entregue | T22: Crie uma ilustração QUADRADA (1:1) para a arte de uma carta de um jogo de cartas de fantasia chamado Desvario. Estilo: ilustração de livro de contos em aquarela e nanquim, muito detalhada, traço fino, clima caprichoso e surreal, o MESMO estilo da imagem de referência do Sr. Pontual. Carta DSV-018, "A Porta Que Não Estava Lá". Cena: Porta de madeira ornamentada, entreaberta, flutuando no meio do nada sem parede. Luz colorida sai pela fresta. Um soldado-régua cinzento dá de cara com ela no meio do ataque. Paleta: cores quentes, vivas e saturadas; formas curvas e orgânicas. Composição: assunto principal centralizado e inteiro, ocupando cerca de 60% da imagem, com cenário ao fundo e margem livre nas bordas; precisa ser legível em miniatura. IMPORTANTE: apenas a ilustração, SEM moldura, SEM borda, SEM nome da carta, SEM estrelas, SEM ATK/DEF, SEM textos ou letreiros e SEM marca d'água.
A23: DSV-019 | B23: Espelho do Avesso | C23: Armadilha | D23: Armadilha Normal | J23: A · Sonhadores de Desvario | K23: 3 | L23: ★ | M23: Biblioteca de Portas | N23: Quando um monstro do oponente declarar um ataque: destrua o monstro atacante. | P23: Espelho alto de moldura rococó; o reflexo mostra o atacante de cabeça para baixo se desfazendo em cacos. Rachaduras finas brilhando em azul-prateado. | Q23: dsv-019-espelho-do-avesso.webp | R23: Entregue | T23: Crie uma ilustração QUADRADA (1:1) para a arte de uma carta de um jogo de cartas de fantasia chamado Desvario. Estilo: ilustração de livro de contos em aquarela e nanquim, muito detalhada, traço fino, clima caprichoso e surreal, o MESMO estilo da imagem de referência do Sr. Pontual. Carta DSV-019, "Espelho do Avesso". Cena: Espelho alto de moldura rococó; o reflexo mostra o atacante de cabeça para baixo se desfazendo em cacos. Rachaduras finas brilhando em azul-prateado. Paleta: cores quentes, vivas e saturadas; formas curvas e orgânicas. Composição: assunto principal centralizado e inteiro, ocupando cerca de 60% da imagem, com cenário ao fundo e margem livre nas bordas; precisa ser legível em miniatura. IMPORTANTE: apenas a ilustração, SEM moldura, SEM borda, SEM nome da carta, SEM estrelas, SEM ATK/DEF, SEM textos ou letreiros e SEM marca d'água.
A24: DSV-020 | B24: Carimbo de Indeferido | C24: Armadilha | D24: Armadilha de Resposta | J24: B · Ordem Cinzenta | K24: 2 | M24: Cidadela Cinzenta | N24: Pague 1000 PL: anule a ativação de uma carta de Magia e destrua-a. | P24: Carimbo gigante descendo sobre uma carta mágica brilhante, deixando a marca 'INDEFERIDO' em vermelho, a única cor da cena. O resto é cinza. | Q24: dsv-020-carimbo-de-indeferido.webp | R24: Entregue | T24: Crie uma ilustração QUADRADA (1:1) para a arte de uma carta de um jogo de cartas de fantasia chamado Desvario. Estilo: ilustração de livro de contos em aquarela e nanquim, muito detalhada, traço fino, clima caprichoso e surreal, o MESMO estilo da imagem de referência do Sr. Pontual. Carta DSV-020, "Carimbo de Indeferido". Cena: Carimbo gigante descendo sobre uma carta mágica brilhante, deixando a marca 'INDEFERIDO' em vermelho, a única cor da cena. O resto é cinza. Paleta: quase monocromática, em tons de cinza, grafite e nanquim; formas retas, rígidas e geométricas; atmosfera burocrática e opressiva. Se a descrição citar um elemento colorido, ele é a ÚNICA cor da cena. Composição: assunto principal centralizado e inteiro, ocupando cerca de 60% da imagem, com cenário ao fundo e margem livre nas bordas; precisa ser legível em miniatura. IMPORTANTE: apenas a ilustração, SEM moldura, SEM borda, SEM nome da carta, SEM estrelas, SEM ATK/DEF, SEM outros textos além da palavra citada entre aspas na cena, escrita corretamente e SEM marca d'água.
A25: DSV-021 | B25: Esquadro Guardião | C25: Monstro Normal | D25: Normal | E25: 4 | F25: CINZA | G25: Burocrata | H25: 1200 | I25: 2000 | J25: B · Ordem Cinzenta | K25: 3 | M25: Cidadela Cinzenta | N25: — | O25: Noventa graus. Nem um a mais, nem um a menos. Nenhum sonho passa por ele sem estar no ângulo correto. | P25: Guarda robusto com corpo em forma de esquadro de metal, escudo retangular e pés quadrados cravados no chão, bloqueando um portão cinza. | Q25: dsv-021-esquadro-guardiao.webp | R25: Entregue | T25: Crie uma ilustração QUADRADA (1:1) para a arte de uma carta de um jogo de cartas de fantasia chamado Desvario. Estilo: ilustração de livro de contos em aquarela e nanquim, muito detalhada, traço fino, clima caprichoso e surreal, o MESMO estilo da imagem de referência do Sr. Pontual. Carta DSV-021, "Esquadro Guardião". Cena: Guarda robusto com corpo em forma de esquadro de metal, escudo retangular e pés quadrados cravados no chão, bloqueando um portão cinza. Paleta: quase monocromática, em tons de cinza, grafite e nanquim; formas retas, rígidas e geométricas; atmosfera burocrática e opressiva. Se a descrição citar um elemento colorido, ele é a ÚNICA cor da cena. Composição: assunto principal centralizado e inteiro, ocupando cerca de 60% da imagem, com cenário ao fundo e margem livre nas bordas; precisa ser legível em miniatura. IMPORTANTE: apenas a ilustração, SEM moldura, SEM borda, SEM nome da carta, SEM estrelas, SEM ATK/DEF, SEM textos ou letreiros e SEM marca d'água.
A26: DSV-022 | B26: Clipe Espião | C26: Monstro de Efeito | D26: Efeito (FLIP) | E26: 1 | F26: CINZA | G26: Burocrata | H26: 200 | I26: 300 | J26: B · Ordem Cinzenta | K26: 2 | M26: Cidadela Cinzenta | N26: FLIP: olhe a mão do oponente. | O26: Prende-se a qualquer documento, e a qualquer segredo. | P26: Clipe de papel retorcido em forma de bichinho, com óculos escuros minúsculos, espiando de trás de uma pilha de pastas, lupa na mão. | Q26: dsv-022-clipe-espiao.webp | R26: Entregue | T26: Crie uma ilustração QUADRADA (1:1) para a arte de uma carta de um jogo de cartas de fantasia chamado Desvario. Estilo: ilustração de livro de contos em aquarela e nanquim, muito detalhada, traço fino, clima caprichoso e surreal, o MESMO estilo da imagem de referência do Sr. Pontual. Carta DSV-022, "Clipe Espião". Cena: Clipe de papel retorcido em forma de bichinho, com óculos escuros minúsculos, espiando de trás de uma pilha de pastas, lupa na mão. Paleta: quase monocromática, em tons de cinza, grafite e nanquim; formas retas, rígidas e geométricas; atmosfera burocrática e opressiva. Se a descrição citar um elemento colorido, ele é a ÚNICA cor da cena. Composição: assunto principal centralizado e inteiro, ocupando cerca de 60% da imagem, com cenário ao fundo e margem livre nas bordas; precisa ser legível em miniatura. IMPORTANTE: apenas a ilustração, SEM moldura, SEM borda, SEM nome da carta, SEM estrelas, SEM ATK/DEF, SEM textos ou letreiros e SEM marca d'água.
A27: DSV-023 | B27: Secretária de Mil Gavetas | C27: Monstro de Efeito | D27: Efeito | E27: 4 | F27: CINZA | G27: Burocrata | H27: 1500 | I27: 1500 | J27: B · Ordem Cinzenta | K27: 3 | M27: Cidadela Cinzenta | N27: Uma vez por turno: você pode descartar 1 carta para comprar 1 carta. | O27: Tudo está arquivado. Achar é que é o problema. | P27: Senhora alta e séria cujo corpo é um arquivo de aço com dezenas de gavetas, algumas abertas e cheias de fichas. Coque apertado com lápis espetados, óculos de meia-lua. | Q27: dsv-023-secretaria-de-mil-gavetas.webp | R27: Entregue | T27: Crie uma ilustração QUADRADA (1:1) para a arte de uma carta de um jogo de cartas de fantasia chamado Desvario. Estilo: ilustração de livro de contos em aquarela e nanquim, muito detalhada, traço fino, clima caprichoso e surreal, o MESMO estilo da imagem de referência do Sr. Pontual. Carta DSV-023, "Secretária de Mil Gavetas". Cena: Senhora alta e séria cujo corpo é um arquivo de aço com dezenas de gavetas, algumas abertas e cheias de fichas. Coque apertado com lápis espetados, óculos de meia-lua. Paleta: quase monocromática, em tons de cinza, grafite e nanquim; formas retas, rígidas e geométricas; atmosfera burocrática e opressiva. Se a descrição citar um elemento colorido, ele é a ÚNICA cor da cena. Composição: assunto principal centralizado e inteiro, ocupando cerca de 60% da imagem, com cenário ao fundo e margem livre nas bordas; precisa ser legível em miniatura. IMPORTANTE: apenas a ilustração, SEM moldura, SEM borda, SEM nome da carta, SEM estrelas, SEM ATK/DEF, SEM textos ou letreiros e SEM marca d'água.
A28: DSV-024 | B28: Apontador Voraz | C28: Monstro de Efeito | D28: Efeito | E28: 3 | F28: CINZA | G28: Burocrata | H28: 1400 | I28: 800 | J28: B · Ordem Cinzenta | K28: 2 | M28: Cidadela Cinzenta | N28: Se esta carta destruir um monstro do oponente em batalha: o oponente descarta 1 carta aleatória da mão. | O28: Aponta tudo até sobrar só a ponta, e depois nem ela. | P28: Apontador de metal com boca cheia de dentes de lâmina, mastigando um lápis de cor (único ponto colorido). Aparas de lápis voam ao redor. | Q28: dsv-024-apontador-voraz.webp | R28: Entregue | T28: Crie uma ilustração QUADRADA (1:1) para a arte de uma carta de um jogo de cartas de fantasia chamado Desvario. Estilo: ilustração de livro de contos em aquarela e nanquim, muito detalhada, traço fino, clima caprichoso e surreal, o MESMO estilo da imagem de referência do Sr. Pontual. Carta DSV-024, "Apontador Voraz". Cena: Apontador de metal com boca cheia de dentes de lâmina, mastigando um lápis de cor (único ponto colorido). Aparas de lápis voam ao redor. Paleta: quase monocromática, em tons de cinza, grafite e nanquim; formas retas, rígidas e geométricas; atmosfera burocrática e opressiva. Se a descrição citar um elemento colorido, ele é a ÚNICA cor da cena. Composição: assunto principal centralizado e inteiro, ocupando cerca de 60% da imagem, com cenário ao fundo e margem livre nas bordas; precisa ser legível em miniatura. IMPORTANTE: apenas a ilustração, SEM moldura, SEM borda, SEM nome da carta, SEM estrelas, SEM ATK/DEF, SEM textos ou letreiros e SEM marca d'água.
A29: DSV-025 | B29: Compasso Perfurador | C29: Monstro de Efeito | D29: Efeito | E29: 4 | F29: CINZA | G29: Burocrata | H29: 1600 | I29: 1200 | J29: B · Ordem Cinzenta | K29: 3 | M29: Cidadela Cinzenta | N29: Se esta carta atacar um monstro em Posição de Defesa cuja DEF seja menor que o ATK desta carta: cause ao oponente dano igual à diferença. | O29: Desenha círculos perfeitos. Principalmente em volta dos alvos. | P29: Guerreiro esguio em forma de compasso: uma perna em ponta afiada cravada no chão, a outra traçando um círculo perfeito em volta de uma flor colorida assustada. | Q29: dsv-025-compasso-perfurador.webp | R29: Entregue | T29: Crie uma ilustração QUADRADA (1:1) para a arte de uma carta de um jogo de cartas de fantasia chamado Desvario. Estilo: ilustração de livro de contos em aquarela e nanquim, muito detalhada, traço fino, clima caprichoso e surreal, o MESMO estilo da imagem de referência do Sr. Pontual. Carta DSV-025, "Compasso Perfurador". Cena: Guerreiro esguio em forma de compasso: uma perna em ponta afiada cravada no chão, a outra traçando um círculo perfeito em volta de uma flor colorida assustada. Paleta: quase monocromática, em tons de cinza, grafite e nanquim; formas retas, rígidas e geométricas; atmosfera burocrática e opressiva. Se a descrição citar um elemento colorido, ele é a ÚNICA cor da cena. Composição: assunto principal centralizado e inteiro, ocupando cerca de 60% da imagem, com cenário ao fundo e margem livre nas bordas; precisa ser legível em miniatura. IMPORTANTE: apenas a ilustração, SEM moldura, SEM borda, SEM nome da carta, SEM estrelas, SEM ATK/DEF, SEM textos ou letreiros e SEM marca d'água.
A30: DSV-026 | B30: Borracha Apagadora | C30: Monstro de Efeito | D30: Efeito | E30: 5 | F30: CINZA | G30: Burocrata | H30: 2100 | I30: 1600 | J30: B · Ordem Cinzenta | K30: 2 | M30: Cidadela Cinzenta | N30: Quando esta carta for Invocada por Invocação-Tributo: destrua 1 monstro com a face para cima que o oponente controla e que tenha 1500 ou menos de ATK. | O30: Onde ela passa, nem o rascunho sobrevive. | P30: Criatura massiva de borracha escolar, metade branca metade cinza, rolando sobre uma paisagem colorida e deixando um rastro branco e vazio, com farelos de borracha. | Q30: dsv-026-borracha-apagadora.webp | R30: Entregue | T30: Crie uma ilustração QUADRADA (1:1) para a arte de uma carta de um jogo de cartas de fantasia chamado Desvario. Estilo: ilustração de livro de contos em aquarela e nanquim, muito detalhada, traço fino, clima caprichoso e surreal, o MESMO estilo da imagem de referência do Sr. Pontual. Carta DSV-026, "Borracha Apagadora". Cena: Criatura massiva de borracha escolar, metade branca metade cinza, rolando sobre uma paisagem colorida e deixando um rastro branco e vazio, com farelos de borracha. Paleta: quase monocromática, em tons de cinza, grafite e nanquim; formas retas, rígidas e geométricas; atmosfera burocrática e opressiva. Se a descrição citar um elemento colorido, ele é a ÚNICA cor da cena. Composição: assunto principal centralizado e inteiro, ocupando cerca de 60% da imagem, com cenário ao fundo e margem livre nas bordas; precisa ser legível em miniatura. IMPORTANTE: apenas a ilustração, SEM moldura, SEM borda, SEM nome da carta, SEM estrelas, SEM ATK/DEF, SEM textos ou letreiros e SEM marca d'água.
A31: DSV-027 | B31: Grampeador Colossal | C31: Monstro Normal | D31: Normal | E31: 7 | F31: CINZA | G31: Burocrata | H31: 2600 | I31: 1800 | J31: B · Ordem Cinzenta | K31: 2 | M31: Cidadela Cinzenta | N31: — | O31: Prende o céu ao chão para que nada mais flutue sem autorização. | P31: Grampeador de metal do tamanho de um prédio, boca aberta como mandíbula, grampeando nuvens coloridas ao chão. Soldados-régua pequenos o acompanham. | Q31: dsv-027-grampeador-colossal.webp | R31: Entregue | T31: Crie uma ilustração QUADRADA (1:1) para a arte de uma carta de um jogo de cartas de fantasia chamado Desvario. Estilo: ilustração de livro de contos em aquarela e nanquim, muito detalhada, traço fino, clima caprichoso e surreal, o MESMO estilo da imagem de referência do Sr. Pontual. Carta DSV-027, "Grampeador Colossal". Cena: Grampeador de metal do tamanho de um prédio, boca aberta como mandíbula, grampeando nuvens coloridas ao chão. Soldados-régua pequenos o acompanham. Paleta: quase monocromática, em tons de cinza, grafite e nanquim; formas retas, rígidas e geométricas; atmosfera burocrática e opressiva. Se a descrição citar um elemento colorido, ele é a ÚNICA cor da cena. Composição: assunto principal centralizado e inteiro, ocupando cerca de 60% da imagem, com cenário ao fundo e margem livre nas bordas; precisa ser legível em miniatura. IMPORTANTE: apenas a ilustração, SEM moldura, SEM borda, SEM nome da carta, SEM estrelas, SEM ATK/DEF, SEM textos ou letreiros e SEM marca d'água.
A32: DSV-028 | B32: Formulário em Três Vias | C32: Magia | D32: Magia Normal | J32: B · Ordem Cinzenta | K32: 3 | M32: Cidadela Cinzenta | N32: Compre 2 cartas e depois descarte 1 carta. | P32: Três folhas de formulário idênticas sobrepostas e flutuando, cheias de campos e caixinhas, com um carimbo pairando sobre elas. Ao fundo, uma fila infinita de pessoas cinzentas. | Q32: dsv-028-formulario-em-tres-vias.webp | R32: Entregue | T32: Crie uma ilustração QUADRADA (1:1) para a arte de uma carta de um jogo de cartas de fantasia chamado Desvario. Estilo: ilustração de livro de contos em aquarela e nanquim, muito detalhada, traço fino, clima caprichoso e surreal, o MESMO estilo da imagem de referência do Sr. Pontual. Carta DSV-028, "Formulário em Três Vias". Cena: Três folhas de formulário idênticas sobrepostas e flutuando, cheias de campos e caixinhas, com um carimbo pairando sobre elas. Ao fundo, uma fila infinita de pessoas cinzentas. Paleta: quase monocromática, em tons de cinza, grafite e nanquim; formas retas, rígidas e geométricas; atmosfera burocrática e opressiva. Se a descrição citar um elemento colorido, ele é a ÚNICA cor da cena. Composição: assunto principal centralizado e inteiro, ocupando cerca de 60% da imagem, com cenário ao fundo e margem livre nas bordas; precisa ser legível em miniatura. IMPORTANTE: apenas a ilustração, SEM moldura, SEM borda, SEM nome da carta, SEM estrelas, SEM ATK/DEF, SEM textos ou letreiros e SEM marca d'água.
A33: DSV-029 | B33: Cidadela Cinzenta | C33: Magia | D33: Magia de Campo | J33: B · Ordem Cinzenta | K33: 2 | M33: Cidadela Cinzenta | N33: Todos os monstros CINZA no campo ganham 300 de ATK e DEF. Todos os monstros que não são CINZA perdem 200 de ATK. | P33: Cidade monumental de prédios idênticos, retos e cinzentos, numa grade perfeita sob um céu sem nuvens, com uma torre-régua altíssima no centro. Nenhuma cor, sem personagens. | Q33: dsv-029-cidadela-cinzenta.webp | R33: Entregue | T33: Crie uma ilustração QUADRADA (1:1) para a arte de uma carta de um jogo de cartas de fantasia chamado Desvario. Estilo: ilustração de livro de contos em aquarela e nanquim, muito detalhada, traço fino, clima caprichoso e surreal, o MESMO estilo da imagem de referência do Sr. Pontual. Carta DSV-029, "Cidadela Cinzenta". Cena: Cidade monumental de prédios idênticos, retos e cinzentos, numa grade perfeita sob um céu sem nuvens, com uma torre-régua altíssima no centro. Nenhuma cor, sem personagens. Paleta: quase monocromática, em tons de cinza, grafite e nanquim; formas retas, rígidas e geométricas; atmosfera burocrática e opressiva. Se a descrição citar um elemento colorido, ele é a ÚNICA cor da cena. Composição: assunto principal centralizado e inteiro, ocupando cerca de 60% da imagem, com cenário ao fundo e margem livre nas bordas; precisa ser legível em miniatura. IMPORTANTE: apenas a ilustração, SEM moldura, SEM borda, SEM nome da carta, SEM estrelas, SEM ATK/DEF, SEM textos ou letreiros e SEM marca d'água.
A34: DSV-030 | B34: Linha Reta | C34: Magia | D34: Magia de Equipamento | J34: B · Ordem Cinzenta | K34: 2 | M34: Cidadela Cinzenta | N34: Só pode ser equipada em um monstro CINZA. O monstro equipado ganha 700 de ATK. | P34: Linha reta perfeita em grafite cortando a imagem de ponta a ponta, 'endireitando' um rio sinuoso, uma árvore torta e um arco-íris no caminho. | Q34: dsv-030-linha-reta.webp | R34: Entregue | T34: Crie uma ilustração QUADRADA (1:1) para a arte de uma carta de um jogo de cartas de fantasia chamado Desvario. Estilo: ilustração de livro de contos em aquarela e nanquim, muito detalhada, traço fino, clima caprichoso e surreal, o MESMO estilo da imagem de referência do Sr. Pontual. Carta DSV-030, "Linha Reta". Cena: Linha reta perfeita em grafite cortando a imagem de ponta a ponta, 'endireitando' um rio sinuoso, uma árvore torta e um arco-íris no caminho. Paleta: quase monocromática, em tons de cinza, grafite e nanquim; formas retas, rígidas e geométricas; atmosfera burocrática e opressiva. Se a descrição citar um elemento colorido, ele é a ÚNICA cor da cena. Composição: assunto principal centralizado e inteiro, ocupando cerca de 60% da imagem, com cenário ao fundo e margem livre nas bordas; precisa ser legível em miniatura. IMPORTANTE: apenas a ilustração, SEM moldura, SEM borda, SEM nome da carta, SEM estrelas, SEM ATK/DEF, SEM outros textos além da palavra citada entre aspas na cena, escrita corretamente e SEM marca d'água.
A35: DSV-031 | B35: Decreto do Recolher | C35: Magia | D35: Magia Contínua | J35: B · Ordem Cinzenta | K35: 2 | M35: Cidadela Cinzenta | N35: Uma vez por turno: escolha 1 monstro com a face para cima que o oponente controla e mude a posição de batalha dele. | P35: Pergaminho oficial pregado num muro cinza, letras rígidas e selo de cera. Sombras de criaturas coloridas se encolhem e se escondem. | Q35: dsv-031-decreto-do-recolher.webp | R35: Entregue | T35: Crie uma ilustração QUADRADA (1:1) para a arte de uma carta de um jogo de cartas de fantasia chamado Desvario. Estilo: ilustração de livro de contos em aquarela e nanquim, muito detalhada, traço fino, clima caprichoso e surreal, o MESMO estilo da imagem de referência do Sr. Pontual. Carta DSV-031, "Decreto do Recolher". Cena: Pergaminho oficial pregado num muro cinza, letras rígidas e selo de cera. Sombras de criaturas coloridas se encolhem e se escondem. Paleta: quase monocromática, em tons de cinza, grafite e nanquim; formas retas, rígidas e geométricas; atmosfera burocrática e opressiva. Se a descrição citar um elemento colorido, ele é a ÚNICA cor da cena. Composição: assunto principal centralizado e inteiro, ocupando cerca de 60% da imagem, com cenário ao fundo e margem livre nas bordas; precisa ser legível em miniatura. IMPORTANTE: apenas a ilustração, SEM moldura, SEM borda, SEM nome da carta, SEM estrelas, SEM ATK/DEF, SEM textos ou letreiros e SEM marca d'água.
A36: DSV-032 | B36: Fila de Espera | C36: Armadilha | D36: Armadilha Contínua | J36: B · Ordem Cinzenta | K36: 2 | M36: Cidadela Cinzenta | N36: Os monstros invocados pelo oponente não podem declarar ataque no turno em que foram invocados. | P36: Fila de criaturas coloridas de Desvario, entediadas, esperando diante de um guichê fechado com a placa 'VOLTE AMANHÃ'. Relógio de parede parado. | Q36: dsv-032-fila-de-espera.webp | R36: Entregue | T36: Crie uma ilustração QUADRADA (1:1) para a arte de uma carta de um jogo de cartas de fantasia chamado Desvario. Estilo: ilustração de livro de contos em aquarela e nanquim, muito detalhada, traço fino, clima caprichoso e surreal, o MESMO estilo da imagem de referência do Sr. Pontual. Carta DSV-032, "Fila de Espera". Cena: Fila de criaturas coloridas de Desvario, entediadas, esperando diante de um guichê fechado com a placa 'VOLTE AMANHÃ'. Relógio de parede parado. Paleta: quase monocromática, em tons de cinza, grafite e nanquim; formas retas, rígidas e geométricas; atmosfera burocrática e opressiva. Se a descrição citar um elemento colorido, ele é a ÚNICA cor da cena. Composição: assunto principal centralizado e inteiro, ocupando cerca de 60% da imagem, com cenário ao fundo e margem livre nas bordas; precisa ser legível em miniatura. IMPORTANTE: apenas a ilustração, SEM moldura, SEM borda, SEM nome da carta, SEM estrelas, SEM ATK/DEF, SEM outros textos além da palavra citada entre aspas na cena, escrita corretamente e SEM marca d'água.
A37: DSV-033 | B37: Auditoria Surpresa | C37: Armadilha | D37: Armadilha Normal | J37: B · Ordem Cinzenta | K37: 3 | M37: Cidadela Cinzenta | N37: Quando o oponente Invocar por Invocação-Normal um monstro com 1500 ou mais de ATK: destrua esse monstro. | P37: Alçapão se abrindo no chão sob um monstro colorido, com três auditores cinzentos de prancheta surgindo de baixo, anotando tudo. | Q37: dsv-033-auditoria-surpresa.webp | R37: Entregue | T37: Crie uma ilustração QUADRADA (1:1) para a arte de uma carta de um jogo de cartas de fantasia chamado Desvario. Estilo: ilustração de livro de contos em aquarela e nanquim, muito detalhada, traço fino, clima caprichoso e surreal, o MESMO estilo da imagem de referência do Sr. Pontual. Carta DSV-033, "Auditoria Surpresa". Cena: Alçapão se abrindo no chão sob um monstro colorido, com três auditores cinzentos de prancheta surgindo de baixo, anotando tudo. Paleta: quase monocromática, em tons de cinza, grafite e nanquim; formas retas, rígidas e geométricas; atmosfera burocrática e opressiva. Se a descrição citar um elemento colorido, ele é a ÚNICA cor da cena. Composição: assunto principal centralizado e inteiro, ocupando cerca de 60% da imagem, com cenário ao fundo e margem livre nas bordas; precisa ser legível em miniatura. IMPORTANTE: apenas a ilustração, SEM moldura, SEM borda, SEM nome da carta, SEM estrelas, SEM ATK/DEF, SEM textos ou letreiros e SEM marca d'água.
A39: Resumo
A40: Total de cartas | B40: =COUNTA($A$5:$A$37)
A41: Monstros Normais | B41: =COUNTIF($C$5:$C$37,"Monstro Normal")
A42: Monstros de Efeito | B42: =COUNTIF($C$5:$C$37,"Monstro de Efeito")
...

Sheet Decks
A1: Decks iniciais: 40 cartas cada (máx. 3 cópias por carta)
A2: As quantidades vêm da aba 'Cartas' (coluna 'Cópias no deck'). Altere lá e os totais aqui se atualizam.
A4: A · Sonhadores de Desvario | G4: B · Ordem Cinzenta
A5: Código | B5: Carta | C5: Categoria | D5: Subtipo | E5: Cópias | G5: Código | H5: Carta | I5: Categoria | J5: Subtipo | K5: Cópias
A6: =Cartas!A5 | B6: =Cartas!B5 | C6: =Cartas!C5 | D6: =Cartas!D5 | E6: =Cartas!K5 | G6: =Cartas!A9 | H6: =Cartas!B9 | I6: =Cartas!C9 | J6: =Cartas!D9 | K6: =Cartas!K9
A7: =Cartas!A6 | B7: =Cartas!B6 | C7: =Cartas!C6 | D7: =Cartas!D6 | E7: =Cartas!K6 | G7: =Cartas!A25 | H7: =Cartas!B25 | I7: =Cartas!C25 | J7: =Cartas!D25 | K7: =Cartas!K25
A8: =Cartas!A7 | B8: =Cartas!B7 | C8: =Cartas!C7 | D8: =Cartas!D7 | E8: =Cartas!K7 | G8: =Cartas!A31 | H8: =Cartas!B31 | I8: =Cartas!C31 | J8: =Cartas!D31 | K8: =Cartas!K31
A9: =Cartas!A8 | B9: =Cartas!B8 | C9: =Cartas!C8 | D9: =Cartas!D8 | E9: =Cartas!K8 | G9: =Cartas!A16 | H9: =Cartas!B16 | I9: =Cartas!C16 | J9: =Cartas!D16 | K9: =Cartas!K16
A10: =Cartas!A10 | B10: =Cartas!B10 | C10: =Cartas!C10 | D10: =Cartas!D10 | E10: =Cartas!K10 | G10: =Cartas!A17 | H10: =Cartas!B17 | I10: =Cartas!C17 | J10: =Cartas!D17 | K10: =Cartas!K17
A11: =Cartas!A11 | B11: =Cartas!B11 | C11: =Cartas!C11 | D11: =Cartas!D11 | E11: =Cartas!K11 | G11: =Cartas!A26 | H11: =Cartas!B26 | I11: =Cartas!C26 | J11: =Cartas!D26 | K11: =Cartas!K26
A12: =Cartas!A12 | B12: =Cartas!B12 | C12: =Cartas!C12 | D12: =Cartas!D12 | E12: =Cartas!K12 | G12: =Cartas!A27 | H12: =Cartas!B27 | I12: =Cartas!C27 | J12: =Cartas!D27 | K12: =Cartas!K27
A13: =Cartas!A13 | B13: =Cartas!B13 | C13: =Cartas!C13 | D13: =Cartas!D13 | E13: =Cartas!K13 | G13: =Cartas!A28 | H13: =Cartas!B28 | I13: =Cartas!C28 | J13: =Cartas!D28 | K13: =Cartas!K28
A14: =Cartas!A14 | B14: =Cartas!B14 | C14: =Cartas!C14 | D14: =Cartas!D14 | E14: =Cartas!K14 | G14: =Cartas!A29 | H14: =Cartas!B29 | I14: =Cartas!C29 | J14: =Cartas!D29 | K14: =Cartas!K29
A15: =Cartas!A15 | B15: =Cartas!B15 | C15: =Cartas!C15 | D15: =Cartas!D15 | E15: =Cartas!K15 | G15: =Cartas!A30 | H15: =Cartas!B30 | I15: =Cartas!C30 | J15: =Cartas!D30 | K15: =Cartas!K30
A16: =Cartas!A18 | B16: =Cartas!B18 | C16: =Cartas!C18 | D16: =Cartas!D18 | E16: =Cartas!K18 | G16: =Cartas!A32 | H16: =Cartas!B32 | I16: =Cartas!C32 | J16: =Cartas!D32 | K16: =Cartas!K32
A17: =Cartas!A19 | B17: =Cartas!B19 | C17: =Cartas!C19 | D17: =Cartas!D19 | E17: =Cartas!K19 | G17: =Cartas!A33 | H17: =Cartas!B33 | I17: =Cartas!C33 | J17: =Cartas!D33 | K17: =Cartas!K33
A18: =Cartas!A20 | B18: =Cartas!B20 | C18: =Cartas!C20 | D18: =Cartas!D20 | E18: =Cartas!K20 | G18: =Cartas!A34 | H18: =Cartas!B34 | I18: =Cartas!C34 | J18: =Cartas!D34 | K18: =Cartas!K34
A19: =Cartas!A21 | B19: =Cartas!B21 | C19: =Cartas!C21 | D19: =Cartas!D21 | E19: =Cartas!K21 | G19: =Cartas!A35 | H19: =Cartas!B35 | I19: =Cartas!C35 | J19: =Cartas!D35 | K19: =Cartas!K35
A20: =Cartas!A22 | B20: =Cartas!B22 | C20: =Cartas!C22 | D20: =Cartas!D22 | E20: =Cartas!K22 | G20: =Cartas!A24 | H20: =Cartas!B24 | I20: =Cartas!C24 | J20: =Cartas!D24 | K20: =Cartas!K24
A21: =Cartas!A23 | B21: =Cartas!B23 | C21: =Cartas!C23 | D21: =Cartas!D23 | E21: =Cartas!K23 | G21: =Cartas!A36 | H21: =Cartas!B36 | I21: =Cartas!C36 | J21: =Cartas!D36 | K21: =Cartas!K36
G22: =Cartas!A37 | H22: =Cartas!B37 | I22: =Cartas!C37 | J22: =Cartas!D37 | K22: =Cartas!K37
D23: Monstros | E23: =SUMIF(C6:C21,"Monstro Normal",E6:E21)+SUMIF(C6:C21,"Monstro de Efeito",E6:E21)
D24: Magias | E24: =SUMIF(C6:C21,"Magia",E6:E21) | J24: Monstros | K24: =SUMIF(I6:I22,"Monstro Normal",K6:K22)+SUMIF(I6:I22,"Monstro de Efeito",K6:K22)
D25: Armadilhas | E25: =SUMIF(C6:C21,"Armadilha",E6:E21) | J25: Magias | K25: =SUMIF(I6:I22,"Magia",K6:K22)
D26: TOTAL | E26: =SUM(E6:E21) | J26: Armadilhas | K26: =SUMIF(I6:I22,"Armadilha",K6:K22)
D27: Deck válido? | E27: =IF(AND(E26>=40,E26<=60,MAX(E6:E21)<=3),"SIM","NÃO") | J27: TOTAL | K27: =SUM(K6:K22)
D28: Cartas diferentes | E28: =COUNTA(A6:A21) | J28: Deck válido? | K28: =IF(AND(K27>=40,K27<=60,MAX(K6:K22)<=3),"SIM","NÃO")
J29: Cartas diferentes | K29: =COUNTA(G6:G22)

Sheet História e guia de arte
A1: Desvario: O Reino do Avesso
A3: A história
A4: O reino | B4: Desvario é um reino do outro lado da tinta, onde nada faz sentido, e é exatamente isso que o mantém vivo. Rios de chá correm morro acima, relógios andam para trás, flores fofocam sobre o futuro e portas aparecem onde bem entendem. A imaginação é a força que sustenta o mundo: quanto mais absurdo, mais colorido e mais vivo.
A5: A ameaça | B5: O Arquiteto Cinzento surgiu das margens de um caderno esquecido. Ele odeia o absurdo e acredita que um mundo sem erros é um mundo perfeito. Com a Ordem Cinzenta, um exército de materiais de escritório vivos (réguas, esquadros, carimbos, borrachas, grampeadores), ele está "corrigindo" Desvario: endireita o que é torto, apaga as cores, carimba os sonhos como INDEFERIDO e transforma tudo numa planta arquitetônica sem vida.
A6: O herói | B6: O Sonhador de Tinta é uma pessoa comum do nosso mundo que pisou numa poça de tinta e caiu do outro lado. Por onde passa, a tinta que escorre de suas mãos e da sua capa devolve as cores ao chão. Ele é a última esperança de Desvario.
A7: O objetivo | B7: Reunir as Cartas de Devaneio, os habitantes e as magias do reino, e duelar contra a Ordem Cinzenta, libertando região por região até chegar à Cidadela Cinzenta e derrotar o Arquiteto. Cada duelo vencido devolve a cor a um pedaço do mundo.
A8: As regiões
A9: Ponto de partida | B9: Não é uma região de Desvario: é a Poça de Tinta, numa rua comum do nosso mundo, que reflete um céu impossível e serve de passagem para o reino.
A10: Bosque das Horas Tortas | B10: Floresta onde as árvores são relógios de pêndulo e as horas andam para qualquer lado. Luz dourada de fim de tarde. Bronze, âmbar e musgo. Criaturas do atributo TEMPO.
A11: Mar de Chá Morno | B11: Um mar de chá quente com ilhas de pires, xícaras-barco e vapor perfumado. Âmbar, creme, porcelana e renda. Criaturas do atributo CHÁ.
A12: Biblioteca de Portas | B12: Uma biblioteca infinita onde cada estante é uma porta e cada espelho mostra o avesso das coisas. Noite azul, prata e estrelas. Criaturas do atributo ESPELHO.
A13: Jardim de Xadrez Vivo | B13: Jardim em formato de tabuleiro, com peças de xadrez que andam sozinhas, flores falantes e brinquedos que ganham vida. Verdes vivos e quadriculados. Criaturas dos atributos FOLHA e TINTA.
A14: Cidadela Cinzenta | B14: A capital da Ordem Cinzenta: prédios idênticos numa grade perfeita, filas intermináveis, guichês e carimbos. Nenhuma cor. Criaturas do atributo CINZA.
A15: Guia visual para as artes
A16: Estilo geral | B16: Ilustração de livro de contos vitoriano, em aquarela e nanquim, levemente surreal e caprichosa. Personagens expressivos, com formas curvas e orgânicas.
A17: Regra de ouro | B17: O lado de Desvario é COLORIDO, CURVO e VIVO. O lado da Ordem Cinzenta é CINZA, RETO e RÍGIDO. Nas cartas CINZA, a única cor permitida é a do que está sendo apagado ou carimbado (uma flor, um lápis de cor, o 'INDEFERIDO' vermelho).
A18: Formato | B18: Quadrado 1:1, mínimo de 600×600 px, sem texto e sem moldura (a moldura da carta é feita pelo site). Arquivo .webp ou .jpg com menos de 200 KB. Nome do arquivo conforme a coluna 'Nome do arquivo da arte' da aba Cartas.
A19: Composição | B19: Personagem centralizado e legível mesmo em tamanho pequeno (a carta aparece como miniatura no catálogo). Evite detalhes importantes nas bordas.
A20: Prompt base (IA) | B20: Victorian storybook illustration, watercolor and ink, whimsical surreal wonderland, saturated colors, square composition, centered subject, no text, no border — [cole aqui a 'Ideia de arte' traduzida]
A21: Prompt base CINZA | B21: Victorian storybook illustration, ink and graphite, monochrome grey palette, rigid straight lines, bureaucratic office supplies come to life, square composition, centered subject, no text, no border — [ideia de arte]
A22: Créditos | B22: Anote a ferramenta ou o artista de cada arte. O professor pede as fontes das imagens no README.
A23: Atributos (elementos)
A24: CHÁ | B24: Xícara · âmbar #C8782A · calor, conforto, adivinhação
A25: TEMPO | B25: Ampulheta · bronze #B08D57 · relógios, atrasos, horas tortas
A26: TINTA | B26: Gota · roxo #6B3FA0 · sonhos, cores, imaginação
A27: ESPELHO | B27: Losango refletido · prata-azulado #7FB7C9 · reflexos, inversões, ilusão
A28: FOLHA | B28: Folha · verde #4E8F4A · jardins, plantas, xadrez vivo
A29: CINZA | B29: Esquadro · cinza #7A7A7A · a Ordem Cinzenta, regras, carimbos

Sheet Regras
A1: Regras: Yu-Gi-Oh! clássico (sem Fusão e sem Ritual)
A3: Objetivo | B3: Reduzir os Pontos de Lucidez (PL) do oponente de 8000 para 0. Também vence quem fizer o oponente precisar comprar com o Deck vazio.
A4: Deck | B4: De 40 a 60 cartas, com no máximo 3 cópias de cada. Mão inicial de 5 cartas.
A5: Fases do turno | B5: 1) Compra (inclusive no 1º turno do duelo) · 2) Espera · 3) Principal 1 · 4) Batalha (ninguém ataca no 1º turno do duelo) · 5) Principal 2 · 6) Final (limite de 6 cartas na mão).
A6: Invocação-Normal | B6: 1 por turno (ou Baixar 1 monstro com a face para baixo, em Defesa). Nível 1–4: sem Tributo. Nível 5–6: 1 Tributo. Nível 7+: 2 Tributos.
A7: Invocação-Flip | B7: Virar um monstro com a face para baixo para Posição de Ataque. Ativa os efeitos FLIP.
A8: Posição | B8: Cada monstro pode mudar de posição 1 vez por turno, mas não no turno em que foi invocado.
A9: Batalha ATK × ATK | B9: O monstro de menor ATK é destruído e seu dono perde a diferença. Empate: os dois são destruídos.
